Workbook

Sheet CSE II
A1: S.No. | B1: University Roll No | C1: Library Id | D1: NAME | E1: FATHER NAME | F1: MOTHER NAME | G1: STUDENT MOB. | H1: FATHER MOB | I1: MOTHER MOB | J1: E-Mail ID | K1: GENDER | L1: BRANCH | M1: SEC | N1: Sign. | P1: Address | Q1: Unique id | T1: Year
A2: 1 | B2: 2400290100001 | C2: 2428CSE236 | D2: AADYA SHUKLA | E2: PRASHANT KUMAR SHUKLA | G2: 9045896347 | H2: 9548186777 | I2: 9457471947 | J2: aadya.2428cse236@kiet.edu | K2: F | L2: CSE | M2: A | O2: A | P2: bhupender puri ,gali no 4 modinagar | Q2: 202401100200001 | R2: AADYA | S2: SHUKLA | T2: 2
A3: =IF(M2<>M3,"1",A2+1) -> 2 | B3: 2400290100002 | C3: 2428CSE2420 | D3: AAKASH KUMAR | E3: HARI MOHAN | G3: 7505278027 | H3: 9759057365 | I3: 8923651178 | J3: aakash.2428cse2420@kiet.edu | K3: M | L3: CSE | M3: A | O3: A | P3: Elampur firozabad | Q3: 202401100200002 | R3: AAKASH | S3: KUMAR | T3: 2
A4: =IF(M3<>M4,"1",A3+1) -> 3 | B4: 2400290100003 | C4: 2428CSE1174 | D4: AARAV CHATURVEDI | E4: MUKESH KUMAR CHATURVEDI | G4: 7651922631 | H4: 9369840496 | I4: 6387927966 | J4: aarav.2428cse1174@kiet.edu | K4: M | L4: CSE | M4: A | O4: A | P4: 1/1382,koiriya ghat,thaheri bazar, golaghat ramnagar, varanasi | Q4: 202401100200003 | R4: AARAV | S4: CHATURVEDI | T4: 2
A5: =IF(M4<>M5,"1",A4+1) -> 4 | B5: 2400290100004 | C5: 2428CSE1592 | D5: AASTHA SUDAN | E5: PUSHAPRAJ SUDAN | G5: 7497077108 | H5: 9416958048 | I5: 9034234895 | J5: aastha.2428cse1592@kiet.edu | K5: F | L5: CSE | M5: A | O5: A | P5: House number 1066, maharana pratap chowk, near bypass road, barara | Q5: 202401100200004 | R5: AASTHA | S5: SUDAN | T5: 2
A6: =IF(M5<>M6,"1",A5+1) -> 5 | B6: 2400290100005 | C6: 2428CSE493 | D6: AAYANSH SINGH | E6: PRADEEP KUMAR SINGH | G6: 9119892200 | H6: 9450482200 | I6: 7800404064 | J6: aayansh.2428cse493@kiet.edu | K6: M | L6: CSE | M6: A | O6: A | P6: Bankata Amethia , Bhatpar Rani, Deoria , Uttar Pradesh | Q6: 202401100200005 | R6: AAYANSH | S6: SINGH | T6: 2
A7: =IF(M6<>M7,"1",A6+1) -> 6 | B7: 2400290100006 | C7: 2428CSE1266 | D7: AAYUSH KUMAR | E7: SUNIL KUMAR GUPTA | G7: 8862838503 | H7: 8271516072 | I7: 7903833922 | J7: aayush.2428cse1266@kiet.edu | K7: M | L7: CSE | M7: A | O7: A | P7: bank colony lane number 3b , gola road , patna | Q7: 202401100200006 | R7: AAYUSH | S7: KUMAR | T7: 2
A8: =IF(M7<>M8,"1",A7+1) -> 7 | B8: 2400290100007 | C8: 2428CSE349 | D8: AAYUSHI GUPTA | E8: LALIT KUMAR GUPTA | G8: 7983313055 | H8: 9897230284 | I8: 9760010284 | J8: aayushi.2428cse349@kiet.edu | K8: F | L8: CSE | M8: A | O8: A | P8: HOUSE NO 40 LANE NO 1 RAGHAV PURAM COLONY SAHARANPUR | Q8: 202401100200007 | R8: AAYUSHI | S8: GUPTA | T8: 2
A9: =IF(M8<>M9,"1",A8+1) -> 8 | B9: 2400290100008 | C9: 2428CSE945 | D9: ABHAY PRATAP SINGH | E9: TEJPAL SINGH | G9: 7017044335 | H9: 9927682375 | I9: 8006823757 | J9: abhay.2428cse945@kiet.edu | K9: M | L9: CSE | M9: A | O9: A | P9: village sisana distt baghpat(250609) | Q9: 202401100200008 | R9: ABHAY | S9: PRATAP SINGH | T9: 2
A10: =IF(M9<>M10,"1",A9+1) -> 9 | B10: 2400290100009 | C10: 2428CSE835 | D10: ABHAY SHARMA | E10: SUNIL KUMAR | G10: 9412015532 | H10: 8899414124 | I10: 7505873420 | J10: abhay.2428cse835@kiet.edu | K10: M | L10: CSE | M10: A | O10: A | P10: Village & Post Shyamon Shamshabad Road Agra | Q10: 202401100200009 | R10: ABHAY | S10: SHARMA | T10: 2
A11: =IF(M10<>M11,"1",A10+1) -> 10 | B11: 2400290100010 | C11: 2428CSE905 | D11: ABHIJEET SINGH | E11: SANTOSH KUMAR SINGH | G11: 8738090053 | H11: 9452498933 | I11: 8808496843 | J11: abhijeet.2428cse905@kiet.edu | K11: M | L11: CSE | M11: A | O11: A | P11: Chandan Nagar Colony Rauza Ghazipur | Q11: 202401100200010 | R11: ABHIJEET | S11: SINGH | T11: 2
A12: =IF(M11<>M12,"1",A11+1) -> 11 | B12: 2400290100011 | C12: 2428CSE2093 | D12: ABHIMANYU KUMAR | E12: PREM PRAKASH SINGH | G12: 7764967947 | H12: 9835807947 | I12: 8789492611 | J12: abhimanyu.2428cse209@kiet.edu | K12: M | L12: CSE | M12: A | O12: A | P12: Basantpur kakrahta,PO:Sahdullahpur dhabouli | Q12: 202401100200011 | R12: ABHIMANYU | S12: KUMAR | T12: 2
A13: =IF(M12<>M13,"1",A12+1) -> 12 | B13: 2400290100012 | C13: 2428CSE1425 | D13: ABHINAV KUMAR | E13: MANOHAR KUMAR SRIVASTAVA | G13: 7903192416 | H13: 6386218375 | I13: 9569265944 | J13: abhinav.2428cse1425@kiet.edu | K13: M | L13: CSE | M13: A | O13: A | P13: village-bardiha lala | Q13: 202401100200012 | R13: ABHINAV | S13: KUMAR | T13: 2
A14: =IF(M13<>M14,"1",A13+1) -> 13 | B14: 2400290100013 | C14: 2428CSE2250 | D14: ABHINAV PATHAK | E14: GIRIDHAR PATHAK | G14: 8299761810 | H14: 9452230476 | I14: 9452230476 | J14: abhinav.2428cse2250@kiet.edu | K14: M | L14: CSE | M14: A | O14: A | P14: VILLAGE LILWAHI GHORAWAL SONBHADRA UTTAR PRADESH | Q14: 202401100200013 | R14: ABHINAV | S14: PATHAK | T14: 2
... A74: =IF(M73<>M74,"1",A73+1) -> 73 | B74: 2400290100074 | C74: 2428CSE2077 | D74: ANUSHKA SINGH | E74: ANIL KUMAR | G74: 9759800123 | H74: 7830326488 | I74: 7830326488 | J74: anushka.2428cse2077@kiet.edu | K74: F | L74: CSE | M74: A | O74: A | P74: City One road Rudrapur | Q74: 202401100200074 | R74: ANUSHKA | S74: SINGH | T74: 2
A75: =IF(M74<>M75,"1",A74+1) -> 74 | B75: 202501200200001 | D75: AASTHA VERMA | G75: 9310429899 | J75: aastha.252002001@kiet.edu | K75: F | L75: CSE | M75: A | O75: A | Q75: 202501200200005 | T75: 2
A76: =IF(M75<>M76,"1",A75+1) -> 75 | B76: 202501200200002 | D76: ABHISHEK TIWARI | G76: 8081732367 | J76: abhishek.252002002@kiet.edu | K76: M | L76: CSE | M76: A | O76: A | Q76: 202501200200018 | T76: 2
A77: =IF(M76<>M77,"1",A76+1) -> 76 | B77: 202501200200003 | D77: AMAN PATHAK | G77: 9140404211 | J77: aman.252002003@kiet.edu | K77: M | L77: CSE | M77: A | O77: A | Q77: 202501200200008 | T77: 2
A78: =IF(M77<>M78,"1",A77+1) -> 77 | B78: 202501200200004 | D78: ANSH PANDEY | G78: 9305017358 | J78: ansh.252002004@kiet.edu | K78: M | L78: CSE | M78: A | O78: A | Q78: 202501200200006 | T78: 2
A79: =IF(M78<>M79,"1",A78+1) -> 78 | B79: 202501200200005 | D79: DEEPAK AZAD | G79: 7417027010 | J79: deepak.252002005@kiet.edu | K79: M | L79: CSE | M79: A | O79: A | Q79: 202501200200007 | T79: 2
A80: =IF(M73<>M80,"1",A73+1) -> 1 | B80: 2400290100075 | C80: 2428CSE1631 | D80: APOORVI ANAND | E80: VIJAY ANAND | G80: 7599340630 | H80: 9457474671 | I80: 9457474621 | J80: apoorvi.2428cse1631@kiet.edu | K80: F | L80: CSE | M80: B | O80: B | P80: Pilibhit bypass road opposite Chandralok hospital near Yamaha service center Bareilly | Q80: 202401100200075 | R80: APOORVI | S80: ANAND | T80: 2
A81: =IF(M80<>M81,"1",A80+1) -> 2 | B81: 2400290100076 | C81: 2428CSE2109 | D81: APOORVY GUPTA | E81: SANJAY GUPTA | G81: 9336946409 | H81: 9336724246 | I81: 9161215013 | J81: apoorvy.2428cse2109@kiet.edu | K81: F | L81: CSE | M81: B | O81: B | P81: 65/2 Shivdaspur, Panchwati Nagar | Q81: 202401100200076 | R81: APOORVY | S81: GUPTA | T81: 2
A82: =IF(M81<>M82,"1",A81+1) -> 3 | B82: 2400290100077 | C82: 2428CSE1856 | D82: ARCHIT VERMA | E82: SANJEEV KUMAR | G82: 7900974176 | H82: 9105018094 | I82: 9456403377 | J82: archit.2428cse1856@kiet.edu | K82: M | L82: CSE | M82: B | O82: B | P82: 278, Naya Rasulpur | Q82: 202401100200077 | R82: ARCHIT | S82: VERMA | T82: 2
A83: =IF(M82<>M83,"1",A82+1) -> 4 | B83: 2400290100078 | C83: 2428CSE1979 | D83: ARIN KUMAR MADDHESHIYA | E83: TRIYUGI NATH MADDHESHIYA | G83: 9519164008 | H83: 9793149217 | I83: 6391909805 | J83: arin.2428cse1979@kiet.edu | K83: M | L83: CSE | M83: B | O83: B | P83: Jungle jhajhwa pipiganj | Q83: 202401100200078 | R83: ARIN | S83: KUMAR MADDHESHIYA | T83: 2
A84: =IF(M83<>M84,"1",A83+1) -> 5 | B84: 2400290100079 | C84: 2428CSE2418 | D84: ARIZA RAHMAN | E84: MOHD HASID | G84: 9555915967 | H84: 9415833540 | I84: 9555915967 | J84: ariza.2428cse2418@kiet.edu | K84: F | L84: CSE | M84: B | O84: B | P84: ALI AUSAT COLONY,SIDHARI | Q84: 202401100200079 | R84: ARIZA | S84: RAHMAN | T84: 2
A85: =IF(M84<>M85,"1",A84+1) -> 6 | B85: 2400290100080 | C85: 2428CSE1955 | D85: ARMAN SINGH | E85: LATE SHIV SHARAN SINGH | G85: 6394917385 | H85: 9170571889 | I85: 9170571889 | J85: arman.2428cse1955@kiet.edu | K85: M | L85: CSE | M85: B | O85: B | P85: GRAM+POST: KOLNA,MIRZAPUR | Q85: 202401100200080 | R85: ARMAN | S85: SINGH | T85: 2
A86: =IF(M85<>M86,"1",A85+1) -> 7 | B86: 2400290100081 | C86: 2428CSE1905 | D86: ARMAN VORA | E86: ANISH KUMAR VORA | G86: 7872861381 | H86: 9933018736 | I86: 7679120178 | J86: arman.2428cse1905@kiet.edu | K86: M | L86: CSE | M86: B | O86: B | P86: H.NO-739/1, WARD NO-25, NEAR BHANDRI MARUTI SHOWROOM, BULBULCHATI | Q86: 202401100200081 | R86: ARMAN | S86: VORA | T86: 2
A87: =IF(M86<>M87,"1",A86+1) -> 8 | B87: 2400290100082 | C87: 2428CSE1796 | D87: ARNAV GAUTAM | E87: TARUN GAUTAM | G87: 8445104769 | H87: 9557605479 | I87: 8126847849 | J87: arnav.2428cse1796@kiet.edu | K87: M | L87: CSE | M87: B | O87: B | P87: 41-A Ayodhya kunj A, Arjun Nagar Agra | Q87: 202401100200082 | R87: ARNAV | S87: GAUTAM | T87: 2
A88: =IF(M87<>M88,"1",A87+1) -> 9 | B88: 2400290100083 | C88: 2428CSE1277 | D88: ARPIT PANDEY | E88: UMESH CHANDRA | G88: 9353779499 | H88: 9110686716 | I88: 8019194394 | J88: arpit.2428cse1277@kiet.edu | K88: M | L88: CSE | M88: B | O88: B | P88: MUSTAFABD SARAIYA, KADIPUR, SULTANPUR | Q88: 202401100200083 | R88: ARPIT | S88: PANDEY | T88: 2
A89: =IF(M88<>M89,"1",A88+1) -> 10 | B89: 2400290100084 | C89: 2428CSE1166 | D89: ARPIT RAJPUT | E89: PANKAJ SINGH | G89: 6392871326 | H89: 8726964030 | I89: 8840527979 | J89: arpit.2428cse1166@kiet.edu | K89: M | L89: CSE | M89: B | O89: B | P89: VILL KANTALA POST RUNI DIST FARRUKHABAD | Q89: 202401100200084 | R89: ARPIT | S89: RAJPUT | T89: 2
A90: =IF(M89<>M90,"1",A89+1) -> 11 | B90: 2400290100085 | C90: 2428CSE1396 | D90: ARPIT SRIVASTAVA | E90: SHAILENDRA KUMAR SRIVASTAVA | G90: 7905187079 | H90: 8052662978 | I90: 8052760481 | J90: arpit.2428cse1396@kiet.edu | K90: M | L90: CSE | M90: B | O90: B | P90: 388-I, Azad Nagar Colony, Rustampur, Gorakhpur | Q90: 202401100200085 | R90: ARPIT | S90: SRIVASTAVA | T90: 2
A91: =IF(M90<>M91,"1",A90+1) -> 12 | B91: 2400290100086 | C91: 2428CSE1683 | D91: ARPITA SAHU | E91: JAI PRAKASH SAHU | G91: 7355634916 | H91: 8318449218 | I91: 9580826733 | J91: arpita.2428cse1683@kiet.edu | K91: F | L91: CSE | M91: B | O91: B | P91: BHARAT CHHAPARA , KOTWA ,RANIGANJ BAZAR | Q91: 202401100200086 | R91: ARPITA | S91: SAHU | T91: 2
A92: =IF(M91<>M92,"1",A91+1) -> 13 | B92: 2400290100087 | C92: 2428CSE1357 | D92: ARSAL MASOOD | E92: MASOOD AKBAR | G92: 9557156626 | H92: 9837161566 | I92: 9756519774 | J92: arsal.2428cse1357@kiet.edu | K92: M | L92: CSE | M92: B | O92: B | P92: BAZIGRAN STREET | Q92: 202401100200087 | R92: ARSAL | S92: MASOOD | T92: 2
... A151: =IF(M150<>M151,"1",A150+1) -> 72 | B151: 2400290100147 | C151: 2428CSE1086 | D151: HARDIK RATHORE | E151: VINOD KUMAR RATHORE | G151: 8439683604 | H151: 9935929135 | I151: 8533876875 | J151: hardik.2428cse1086@kiet.edu | K151: M | L151: CSE | M151: B | O151: B | P151: Mahera saray bhognipur kanpur dehat | Q151: 202401100200147 | R151: HARDIK | S151: RATHORE | T151: 2
A152: =IF(M151<>M152,"1",A151+1) -> 73 | B152: 202501200200006 | D152: DEEPAK CHAUDHARY | G152: 6306725551 | J152: deepak.252002006@kiet.edu | K152: M | L152: CSE | M152: B | O152: B | Q152: 2025D00211T01801 | T152: 2
A153: =IF(M152<>M153,"1",A152+1) -> 74 | B153: 202501200200007 | D153: DEV SINGH | G153: 9648153123 | J153: dev.252002007@kiet.edu | K153: M | L153: CSE | M153: B | O153: B | Q153: 202501200200003 | T153: 2
A154: =IF(M153<>M154,"1",A153+1) -> 75 | B154: 202501200200008 | D154: DHEERAJ KUMAR | G154: 7078757352 | J154: dheeraj.252002008@kiet.edu | K154: M | L154: CSE | M154: B | O154: B | Q154: 2025D00211C01803 | T154: 2
A155: =IF(M154<>M155,"1",A154+1) -> 76 | B155: 202501200200009 | D155: DIYA | G155: 6398562445 | J155: diya.252002009@kiet.edu | K155: F | L155: CSE | M155: B | O155: B | Q155: 202501200200002 | T155: 2
A156: =IF(M155<>M156,"1",A155+1) -> 77 | B156: 202501200200010 | D156: GAURI TYAGI | G156: 8868091739 | J156: gauri.252002010@kiet.edu | K156: F | L156: CSE | M156: B | O156: B | Q156: 202501200200013 | T156: 2
A157: =IF(M156<>M157,"1",A156+1) -> 78 | B157: 202501200200011 | D157: GRANTH CHAUHAN | G157: 6398905475 | J157: granth.252002011@kiet.edu | K157: M | L157: CSE | M157: B | O157: B | Q157: 202501200200016 | T157: 2
...

Sheet CSE III
A1: S.No. | B1: University Roll No | C1: Library Id | D1: NAME | E1: FATHER NAME | F1: MOTHER NAME | G1: STUDENT MOB. | H1: FATHER MOB | I1: MOTHER MOB | J1: E-Mail ID | K1: Personal Email id | L1: GENDER | M1: BRANCH | N1: SEC | O1: Sign. | P1: 10th | Q1: 12th | R1: DOB | S1: DOB (DD/MM/YYYY) | U1: Address | V1: Year
A2: 1 | B2: 2300290100001 | C2: 2327CSE1239 | D2: AADARSH KESARWANI | E2: SUNIL KESARWANI | G2: 7348604322 | H2: 6386836667 | I2: 7348604322 | J2: aadarsh.2327cse1239@kiet.edu | K2: adarsh.08122003@gmail.com | L2: MALE | M2: CSE | N2: A | P2: 85.5 | Q2: 86.5 | R2: 37963 | S2: 08/12/2003 | T2: A | U2: 83a/66, juhi hameerpur, juhi colony kanpur nagar up kanpur nagar kanpur nagar 208014kanpur nagar upkanpur nagar | V2: 3
A3: =IF(N2<>N3,"1",A2+1) -> 2 | B3: 2300290100002 | C3: 2327CSE1112 | D3: AAKASH PATHAK | E3: HARIKESH PATHAK | G3: 8791696605 | H3: 8057903565 | I3: 8057903565 | J3: aakash.2327cse1112@kiet.edu | K3: aakashpathak805.a@gmail.com | L3: MALE | M3: CSE | N3: A | P3: 81.83 | Q3: 74.33 | R3: 37924 | S3: 30/10/2003 | T3: A | U3: H. NO. 84, Veena enclave,p.a.c road,subhash nagar,jwalapur Haridwar Haridwar 249407----Haridwar | V3: 3
A4: =IF(N3<>N4,"1",A3+1) -> 3 | B4: 2300290100003 | C4: 2327CSE1050 | D4: AARYAN KUMAR | E4: YOGENDRA KUMAR | G4: 9389633094 | H4: 6398795526 | I4: 9389633094 | J4: aaryan.2327cse1050@kiet.edu | K4: aaryan19ak@gmail.com | L4: MALE | M4: CSE | N4: A | P4: 87.67 | Q4: 91.2 | R4: 38856 | S4: 19/05/2006 | T4: A | U4: h.no126, shahpur nij morta ghaziabad ghazibaad 201003----ghaziabad | V4: 3
A5: =IF(N4<>N5,"1",A4+1) -> 4 | B5: 2300290100004 | C5: 2327CSE1125 | D5: ABHAY PRATAP MAURYA | E5: SATYA VRAT DAS | G5: 7905312943 | H5: 9919280508 | I5: 7905312943 | J5: abhay.2327cse1125@kiet.edu | K5: abhaypratap1213@gmail.com | L5: MALE | M5: CSE | N5: A | P5: 88 | Q5: 78 | R5: 38882 | S5: 14/06/2006 | T5: A | U5: KATAKA MARAUTHA BAHRAICH Bahraich 271903----BAHRAICH | V5: 3
A6: =IF(N5<>N6,"1",A5+1) -> 5 | B6: 2300290100005 | C6: 2327CSE1256 | D6: ABHAY PRATAP SINGH | E6: RAMNIWAS SINGH | F6: TARA DEVI | G6: 9670360309 | H6: 8052724538 | I6: 9670360309 | J6: abhay.2327cse1256@kiet.edu | K6: abhaypratapsingh967036@gmail.com | L6: MALE | M6: CSE | N6: A | P6: 82.2 | Q6: 89.8 | R6: 38353 | S6: 01/01/2005 | T6: A | U6: sathiyaw, fazil nagar gorakhpur kushinagar 274401----gorakhpur | V6: 3
A7: =IF(N6<>N7,"1",A6+1) -> 6 | B7: 2300290100006 | C7: 2327CSE1105 | D7: ABHIJEET KUMAR | E7: SURENDRA KUMAR | F7: GEETA | G7: 8077107461 | H7: 9045666106 | I7: 8859057023 | J7: abhijeet.2327cse1105@kiet.edu | K7: abhijeetkumark.sg@gmail.com | L7: MALE | M7: CSE | N7: A | P7: 90.8 | Q7: 74.2 | R7: 37876 | S7: 12/09/2003 | T7: A | U7: h.no.36, nikat trimurti bhawan sanjay nagar, bareilly bareilly 243001sanjay nagar, bareilly---- | V7: 3
A8: =IF(N7<>N8,"1",A7+1) -> 7 | B8: 2300290100007 | C8: 2327CSE1272 | D8: ABHIJEET VINAY JHA | E8: VINAY KUMAR JHA | G8: 8178422210 | H8: 7503311257 | I8: 9717373622 | J8: abhijeet.2327cse1272@kiet.edu | K8: abhijeetvinayjha@gmail.com | L8: MALE | M8: CSE | N8: A | P8: 96.2 | Q8: 86.8 | R8: 38763 | S8: 15/02/2006 | T8: A | U8: 201/21 lotus welfare society, omicron 03, eachachar greater noida gautam buddha nagar 201310----greater noida | V8: 3
A9: =IF(N8<>N9,"1",A8+1) -> 8 | B9: 2300290100008 | C9: 2327CSE1223 | D9: ABHINAV BATRA | E9: NAVEEN KUMAR | F9: MEENU ARORA | G9: 8979998069 | H9: 9810781666 | I9: 8449579831 | J9: abhinav.2327cse1223@kiet.edu | K9: abhinavbatra1110@gmail.com | L9: MALE | M9: CSE | N9: A | P9: 90.6 | Q9: 90.8 | R9: 38636 | S9: 11/10/2005 | T9: A | U9: SHIVAM VIHAR NEAR PAKWAAN RESTAURANT, MURADNAGAR muradnagar ghaziabad 201206----muradnagar | V9: 3
A10: =IF(N9<>N10,"1",A9+1) -> 9 | B10: 2300290100009 | C10: 2327CSE1056 | D10: ABHINAV KUMAR | E10: MAHESH KUMAR | G10: 7900771385 | H10: 8859430304 | I10: 8979441383 | J10: abhinav.2327cse1056@kiet.edu | K10: mahesh8859430304@gmail.com | L10: MALE | M10: CSE | N10: A | P10: 75.8 | Q10: 88.6 | R10: 38544 | S10: 11/07/2005 | T10: A | U10: b105 meel ford city phase 2, gali no2, rohta road meerut meerut 250002----meerut | V10: 3
A11: =IF(N10<>N11,"1",A10+1) -> 10 | B11: 2300290100010 | C11: 2327CSE1212 | D11: ABHINAV SINGH | E11: GAJENDRA SINGH | G11: 9521399490 | H11: 9415432951 | I11: 9450637391 | J11: abhinav.2327cse1212@kiet.edu | K11: ABHINAVDYBALA10@GMAIL.COM | L11: MALE | M11: CSE | N11: A | P11: 91.6 | Q11: 87.4 | R11: 38324 | S11: 03/12/2004 | T11: A | U11: 37, RANAPUR, NISGAR MU. Bhojpur (Raebareli) Raebareli 229202----Bhojpur (Raebareli) | V11: 3
A12: =IF(N11<>N12,"1",A11+1) -> 11 | B12: 2300290100011 | C12: 2327CSE1124 | D12: ABHINAV TYAGI | E12: RAJAN TYAGI | F12: BABITA TYAGI | G12: 7466977201 | H12: 9837180276 | I12: 9012965228 | J12: abhinav.2327cse1124@kiet.edu | K12: nababhi2244@gmail.com | L12: MALE | M12: CSE | N12: A | P12: 94 | Q12: 95.4 | R12: 38499 | S12: 27/05/2005 | T12: A | U12: kailashpuri ward no10, niwari dehat, ghaziabad ghaziabad ghaziabad 201204----ghaziabad | V12: 3
A13: =IF(N12<>N13,"1",A12+1) -> 12 | B13: 2300290100012 | C13: 2327CSE1198 | D13: ABHISHEK GUPTA | E13: SHRI RAM GUPTA | G13: 6394158352 | H13: 7607442271 | I13: 6394158352 | J13: abhishek.2327cse1198@kiet.edu | K13: abhishekgupta639415@gmail.com | L13: MALE | M13: CSE | N13: A | P13: 77.4 | Q13: 72.2 | R13: 37987 | S13: 01/01/2004 | T13: A | U13: indaurpur urf ghinhapur post mudiyari, tandwa faridpur ambedkar nagar ambedkar nagar 224176post mudiyari, tandwa faridpurambedkar nagar | V13: 3
A14: =IF(N13<>N14,"1",A13+1) -> 13 | B14: 2300290100013 | C14: 2327CSE1182 | D14: ABHISHEK KUMAR YADAV | E14: LALLAN YADAV | G14: 7985265569 | H14: 9569530629 | I14: 9140038259 | J14: abhishek.2327cse1182@kiet.edu | K14: kumarabhishekyadav87@gmail.com | L14: MALE | M14: CSE | N14: A | P14: 98.4 | Q14: 96.2 | R14: 38541 | S14: 08/07/2005 | T14: A | U14: gram anjahi post parwarpar GRAM ANJAHI POST PARWARPAR kushinagar KUSHINAGAR 274305GRAM ANJAHI POST PARWARPARkushinagar | V14: 3
A15: =IF(N14<>N15,"1",A14+1) -> 14 | B15: 2300290100014 | C15: 2327CSE1140 | D15: ABHISHEK SINGH | E15: RAMPALAT | G15: 9335192268 | H15: 9936538093 | I15: 9335192268 | J15: abhishek.2327cse1140@kiet.edu | K15: abhisheksingh33404@gmail.com | L15: MALE | M15: CSE | N15: A | P15: 67.6 | Q15: 59.2 | R15: 38457 | S15: 15/04/2005 | T15: A | U15: rampalat,vill rampur post mansurganj mansurganj MAHARAJGANJ 273165----mansurganj | V15: 3
A16: =IF(N15<>N16,"1",A15+1) -> 15 | B16: 2300290100015 | C16: 2327CSE1047 | D16: ABHISHEK TOMAR | E16: SUDHIR TOMAR | F16: SEEMA TOMAR | G16: 7310932203 | H16: 9760104481 | I16: 9027020588 | J16: abhishek.2327cse1047@kiet.edu | K16: abhishektomarai99@gmail.com | L16: MALE | M16: CSE | N16: A | P16: 80.83 | Q16: 59.8 | R16: 38616 | S16: 21/09/2005 | T16: A | U16: 131/a, punjabi colony shamli MUZAFFARNAGAR Muzaffarnagar 247776shamliMUZAFFARNAGAR | V16: 3
A17: =IF(N16<>N17,"1",A16+1) -> 16 | B17: 2300290100016 | C17: 2327CSE1123 | D17: ADARSH PANWAR | E17: ARUN KUMAR | G17: 7701939359 | H17: 6005266060 | I17: 7302288283 | J17: adarsh.2327cse1123@kiet.edu | K17: adarshpanwar1444@gmail.com | L17: MALE | M17: CSE | N17: A | P17: 77.2 | Q17: 65 | R17: 38094 | S17: 17/04/2004 | T17: A | U17: c 303 sainik vihar, meerut meerut meerut 250001----meerut | V17: 3
A18: =IF(N17<>N18,"1",A17+1) -> 17 | B18: 2300290100017 | C18: 2327CSE1273 | D18: ADITYA BHARDWAJ | E18: PRAVESH BHARDWAJ | F18: RAJANI BHARDWAJ | G18: 8449697271 | H18: 9627883532 | I18: 9193467909 | J18: aditya.2327cse1273@kiet.edu | K18: adibhardwaj0707@gmail.com | L18: MALE | M18: CSE | N18: A | P18: 84.2 | Q18: 74.6 | R18: 38164 | S18: 26/06/2004 | T18: A | U18: 50 rama ashram bihari vilas tundla FIROZABAD Firozabad 283204----FIROZABAD | V18: 3
A19: =IF(N18<>N19,"1",A18+1) -> 18 | B19: 2300290100018 | C19: 2327CSE1197 | D19: ADITYA GIRI | E19: SANJAY KUMAR GIRI | G19: 9650782742 | H19: 9911257884 | I19: 9650782742 | J19: aditya.2327cse1197@kiet.edu | K19: Aditya.2327cse1197@kiet.edu | L19: MALE | M19: CSE | N19: A | P19: 83.83 | Q19: 83.83 | R19: 38188 | S19: 20/07/2004 | T19: A | U19: SALEKHAN PATTI BANGAON JAUNPUR Jaunpur 222125BANGAONJAUNPUR | V19: 3
A20: =IF(N19<>N20,"1",A19+1) -> 19 | B20: 2300290100019 | C20: 2327CSE1168 | D20: ADITYA KUMAR MISHRA | E20: ARVIND KUMAR MISHRA | F20: RANJU MISHRA | G20: 9452760094 | H20: 8318810087 | I20: 9455946751 | J20: aditya.2327cse1168@kiet.edu | K20: adityamishra2245@gmail.com | L20: MALE | M20: CSE | N20: A | P20: 72.8 | Q20: 67.4 | R20: 38462 | S20: 20/04/2005 | T20: A | U20: gram katghara,mahalu,post undura,katghara mahalu mau Mau 221603----mau | V20: 3
A21: =IF(N20<>N21,"1",A20+1) -> 20 | B21: 2300290100020 | C21: 2327CSE1085 | D21: ADITYA PANDEY | E21: SHAILENDRA KUMAR PANDEY | G21: 6387967066 | H21: 9219550436 | I21: 9219550436 | J21: aditya.2327cse1085@kiet.edu | K21: pandeyhere23@gmail.com | L21: MALE | M21: CSE | N21: A | P21: 80 | Q21: 85.6 | R21: 38335 | S21: 14/12/2004 | T21: A | U21: qwa no 2 government press officer coloney aishbagh LUCKNOW Lucknow 226004aishbaghLUCKNOW | V21: 3
A22: =IF(N21<>N22,"1",A21+1) -> 21 | B22: 2300290100021 | C22: 2327CSE1142 | D22: ADITYA RAI | E22: RAJENDA KUMAR RAI | F22: POONAM RAI | G22: 8318290660 | H22: 9451957028 | I22: 7521990790 | J22: aditya.2327cse1142@kiet.edu | K22: raiaditya0106@gmail.com | L22: MALE | M22: CSE | N22: A | P22: 93 | Q22: 92.8 | R22: 38720 | S22: 03/01/2006 | T22: A | U22: shikar garh maharajganj MAHARAJGANJ Maharajganj 273157----MAHARAJGANJ | V22: 3
A23: =IF(N22<>N23,"1",A22+1) -> 22 | B23: 2300290100022 | C23: 2327CSE1284 | D23: ADITYA RAJ | E23: MUKESH KUMAR BHARTI | G23: 7536040246 | H23: 8006661121 | I23: 9675152414 | J23: aditya.2327cse1284@kiet.edu | K23: aadityavivek2002@gmail.com | L23: MALE | M23: CSE | N23: A | P23: 78.67 | Q23: 72 | R23: 38172 | S23: 04/07/2004 | T23: A | U23: villpadeli, postjhuksa, tehdataganj budaun BUDAUN Budaun 243630budaunBUDAUN | V23: 3
A24: =IF(N23<>N24,"1",A23+1) -> 23 | B24: 2300290100023 | C24: 2327CSE1224 | D24: ADITYA SHARMA | E24: RAJESH KUMAR SHARMA | F24: NEELAM SAINI | G24: 8318953338 | H24: 8953185357 | I24: 9695965141 | J24: aditya.2327cse1224@kiet.edu | K24: sharma.adityaaa0001@gmail.com | L24: MALE | M24: CSE | N24: A | P24: 76 | Q24: 54.03 | R24: 38460 | S24: 18/04/2005 | T24: A | U24: gauhar pura shahjahanpur Shahjahanpur 242001----shahjahanpur | V24: 3
A25: =IF(N24<>N25,"1",A24+1) -> 24 | B25: 2300290100024 | C25: 2327CSE1216 | D25: ADITYA YADAV | E25: ARJUN KUMAR YADAV | G25: 9415585070 | H25: 9452049219 | I25: 9120124327 | J25: aditya.2327cse1216@kiet.edu | K25: ay5860840@gmail.com | L25: MALE | M25: CSE | N25: A | P25: 94 | Q25: 86 | R25: 37920 | S25: 26/10/2003 | T25: A | U25: pradhan tola sihapur GORAKHPUR Gorakhpur 273209sihapurGORAKHPUR | V25: 3
A26: =IF(N25<>N26,"1",A25+1) -> 25 | B26: 2300290100025 | C26: 2327CSE1006 | D26: AIMAN SIDDIQUI | E26: KHURRAM ANIS | F26: AFZAL NISHAT | G26: 8445377459 | H26: 9897052951 | I26: 8445377459 | J26: aiman.2327cse1006@kiet.edu | K26: siddiquianisaiman@gmail.com | L26: FEMALE | M26: CSE | N26: A | P26: 93.4 | Q26: 94 | R26: 38460 | S26: 18/04/2005 | T26: A | U26: vill. sikri muzzafarnagar MUZZAFARNAGAR 251308----muzzafarnagar | V26: 3
A27: =IF(N26<>N27,"1",A26+1) -> 26 | B27: 2300290100026 | C27: 2327CSE1023 | D27: AKANKSHA MANDAL | E27: DINESH MANDAL | G27: 9140078995 | H27: 9559338888 | I27: 8840740682 | J27: akanksha.2327cse1023@kiet.edu | K27: akankshamandal04@gmail.com | L27: FEMALE | M27: CSE | N27: A | P27: 95.33 | Q27: 94 | R27: 38199 | S27: 31/07/2004 | T27: A | U27: n12, 266T91, shivrajnagar colony mahmoorgunj, varanasi VARANASI Varanasi 221010mahmoorgunj, varanasiVARANASI | V27: 3
A28: =IF(N27<>N28,"1",A27+1) -> 27 | B28: 2300290100027 | C28: 2327CSE1127 | D28: AKHIL KUMAR | E28: PRAMOD KUMAR | G28: 9044109957 | H28: 9565397678 | I28: 8960020347 | J28: akhil.2327cse1127@kiet.edu | K28: akhil87901@gmail.com | L28: MALE | M28: CSE | N28: A | P28: 88.5 | Q28: 80.33 | R28: 38718 | S28: 01/01/2006 | T28: A | U28: VILLAGE KANAILA KHURD post KANAILA khas village kanaila khurd basti 272301----village kanaila khurd | V28: 3
A29: =IF(N28<>N29,"1",A28+1) -> 28 | B29: 2300290100028 | C29: 2327CSE1204 | D29: AKHILESH SINGH | E29: RANVEER SINGH | F29: RENU SINGH | G29: 9125240079 | H29: 9453283704 | I29: 9919450477 | J29: akhilesh.2327cse1204@kiet.edu | K29: akhileshblp1981@gmail.com | L29: MALE | M29: CSE | N29: A | P29: 80 | Q29: 68.83 | R29: 38365 | S29: 13/01/2005 | T29: A | U29: manyariya manaria balrampur balrampur balrampur 271607----balrampur | V29: 3
A30: =IF(N29<>N30,"1",A29+1) -> 29 | B30: 2300290100029 | C30: 2327CSE1248 | D30: AKSHAT PRAKASH SRIVASTAVA | E30: CHANDRA PRAKASH SRIVASTAVA | G30: 8887595823 | H30: 9453226019 | I30: 9450479997 | J30: akshat.2327cse1248@kiet.edu | K30: akshatsri.0712@gmail.com | L30: MALE | M30: CSE | N30: A | P30: 92.5 | Q30: 94.6 | R30: 38545 | S30: 12/07/2005 | T30: A | U30: a20/14 awas vikas colony, surajkund GORAKHPUR GORAKHPUR GORAKHPUR 273015GORAKHPURGORAKHPUR | V30: 3
A31: =IF(N30<>N31,"1",A30+1) -> 30 | B31: 2300290100030 | C31: 2327CSE1076 | D31: AKSHAT SHUKLA | E31: AKHILESH DATTA SHUKLA | G31: 9044872802 | H31: 6387900214 | I31: 9044872802 | J31: akshat.2327cse1076@kiet.edu | K31: shuklaakshatascom@gmail.com | L31: MALE | M31: CSE | N31: A | P31: 83.5 | Q31: 81.2 | R31: 38237 | S31: 07/09/2004 | T31: A | U31: belva bahuta gonda gonda GONDA 271202gondagonda | V31: 3
A32: =IF(N31<>N32,"1",A31+1) -> 31 | B32: 2300290100031 | C32: 2327CSE1075 | D32: AKSHAY CHAUHAN | E32: DHARMESH CHAUHAN | G32: 7505324445 | H32: 9719302646 | I32: 9634031079 | J32: akshay.2327cse1075@kiet.edu | K32: akshaychau123456@gmail.com | L32: MALE | M32: CSE | N32: A | P32: 88.83 | Q32: 94.83 | R32: 38955 | S32: 26/08/2006 | T32: A | U32: SALARPUR TEHSIL GARHMUKTESHWAR HAPUR HAPUR 245205----HAPUR | V32: 3
A33: =IF(N32<>N33,"1",A32+1) -> 32 | B33: 2300290100032 | C33: 2327CSE1130 | D33: AKSHAY KUMAR DUBEY | E33: RAJESH KUMAR DUBEY | G33: 9264927905 | H33: 8736920066 | I33: 9453767894 | J33: akshay.2327cse1130@kiet.edu | K33: akshaykumardubey023@gmail.com | L33: MALE | M33: CSE | N33: A | P33: 91 | Q33: 93.4 | R33: 38952 | S33: 23/08/2006 | T33: A | U33: d35/116 JANGAMBADI, VARANASI UP VARANASI VARANASI 221001----VARANASI | V33: 3
A34: =IF(N33<>N34,"1",A33+1) -> 33 | B34: 2300290100033 | C34: 2327CSE1173 | D34: AKSHAY MALIK | E34: SATENDRA | G34: 6397937798 | H34: 9536808254 | I34: 9897491360 | J34: akshay.2327cse1173@kiet.edu | K34: akshaymalik2040@gmail.com | L34: MALE | M34: CSE | N34: A | P34: 96 | Q34: 96.6 | R34: 38393 | S34: 10/02/2005 | T34: A | U34: Patti bhitarwal, lak, shamli MUZAFFARNAGAR Muzaffarnagar 247776----MUZAFFARNAGAR | V34: 3
A35: =IF(N34<>N35,"1",A34+1) -> 34 | B35: 2300290100034 | C35: 2327CSE1218 | D35: AKSHIT RAJ | E35: RAM LALA THAKUR | F35: MANJU KUMARI | G35: 7370090365 | H35: 8757405371 | I35: 8757405371 | J35: akshit.2327cse1218@kiet.edu | K35: akshitraj19@gmail.com | L35: MALE | M35: CSE | N35: A | P35: 89 | Q35: 71 | R35: 38398 | S35: 15/02/2005 | T35: A | U35: TEERA JATHMALPUR, SAMASTIPUR BIHAR BIHAR SAMASTIPUR Samastipur 847301BIHARSAMASTIPUR | V35: 3
A36: =IF(N35<>N36,"1",A35+1) -> 35 | B36: 2300290100035 | C36: 2327CSE1133 | D36: AKSHITA SINGH | E36: PRADEEP KUMAR | G36: 7505530395 | H36: 9457646335 | I36: 6395785987 | J36: akshita.2327cse1133@kiet.edu | K36: akshita.10201@gmail.com | L36: FEMALE | M36: CSE | N36: A | P36: 84.8 | Q36: 65.8 | R36: 38547 | S36: 14/07/2005 | T36: A | U36: 53/69, nawab gate near mala talkies, indra colony rampur rampur rampur 244901rampurrampur | V36: 3
A37: =IF(N36<>N37,"1",A36+1) -> 36 | B37: 2300290100036 | C37: 2327CSE1247 | D37: AMAN KUMAR | E37: AWADHESH KUMAR | G37: 8810916986 | H37: 8173801404 | I37: 8418008504 | J37: aman.2327cse1247@kiet.edu | K37: KUMARAMAN131147@GMAIL.COM | L37: MALE | M37: CSE | N37: A | P37: 85.8 | Q37: 65.4 | R37: 38244 | S37: 14/09/2004 | T37: A | U37: KHAGWAL, KHAGWAL, KHAGWAL CHANDAULI CHANDAULI 232104----CHANDAULI | V37: 3
A38: =IF(N37<>N38,"1",A37+1) -> 37 | B38: 2300290100037 | C38: 2327CSE1270 | D38: AMAN KUMAR SINGH | E38: R K SINGH | G38: 7080670307 | H38: 7807469037 | I38: 9340445963 | J38: aman.2327cse1270@kiet.edu | K38: amankumarsinghff@gmail.com | L38: MALE | M38: CSE | N38: A | P38: 86.4 | Q38: 82.6 | R38: 38412 | S38: 01/03/2005 | T38: A | U38: GAHMAR GHAZIPUR GAHMAR GHAZIPUR 232327GHAZIPURGAHMAR | V38: 3
A39: =IF(N38<>N39,"1",A38+1) -> 38 | B39: 2300290100038 | C39: 2327CSE1157 | D39: AMAN SHUKLA | E39: UMESH KUMAR SHUKLA | G39: 6386241172 | H39: 8840096018 | I39: 8840096018 | J39: aman.2327cse1157@kiet.edu | K39: amanshukla0235@gmail.com | L39: MALE | M39: CSE | N39: A | P39: 86.5 | Q39: 87.6 | R39: 38088 | S39: 11/04/2004 | T39: A | U39: 167A, keshav nagar, sitapur road, near surbhi school, nirala nagar LUCKNOW LUCKNOW Lucknow 226020LUCKNOWLUCKNOW | V39: 3
A40: =IF(N39<>N40,"1",A39+1) -> 39 | B40: 2300290100039 | C40: 2327CSE1058 | D40: AMBAR CHAKRAVARTTY | E40: KAUSHIK CHAKRAVARTTY | G40: 8800229312 | H40: 8800229501 | I40: 9821188285 | J40: ambar.2327cse1058@kiet.edu | K40: chakravarttyambar@gmail.com | L40: MALE | M40: CSE | N40: A | P40: 92.33 | Q40: 92.6 | R40: 38512 | S40: 09/06/2005 | T40: A | U40: 101 OAK TOWER,SHIPRA SRISHTI INDIRAPURAM,GHAZIABAD GHAZIABAD GHAZIABAD 201014INDIRAPURAM,GHAZIABADGHAZIABAD | V40: 3
...

Sheet CSE IV
A1: S.No | B1: University Roll No | C1: Library Id | D1: Student Name | E1: Father's Name | F1: SEC. | G1: SIGN. | H1: Semester | I1: GENDER | J1: Email Id | K1: Personal Email id | L1: Mobile No. | M1: F. Mobile No. | O1: 10th | P1: 12th | Q1: DOB | R1: DOB (DD/MM/YYYY) | S1: Residential Status | T1: Address | U1: Year
A2: 1 | B2: 2200290100001 | C2: 2226CSE1014 | D2: AANCHAL GUPTA | E2: ARVIND GUPTA | F2: A | H2: VI | I2: FEMALE | J2: aanchal.2226cse1014@kiet.edu | K2: aanchalgupta0205@gmail.com | L2: 9319360500 | M2: 9810868741 | N2: A | O2: 97.2 | P2: 97.2 | Q2: 38388 | R2: 05/02/2005 | S2: DAY SCHOLAR | T2: H.NO. L104, SECTOR23 SANJAY NAGAR GHAZIABAD SANJAY NAGAR GHAZIABAD 201002SANJAY NAGAR GHAZIABADSANJAY NAGAR | U2: 4
A3: 2 | B3: 2200290100002 | C3: 2226CSE1129 | D3: AARADHYA GUPTA | E3: DEEPAK GUPTA | F3: A | H3: VI | I3: FEMALE | J3: aaradhya.2226cse1129@kiet.edu | K3: aaradhyagupta2810@gmail.com | L3: 7906800884 | M3: 9837321556 | N3: A | O3: --- | P3: --- | Q3: 37922 | R3: 28/10/2003 | S3: HOSTELLER | T3: 9/503 missar murrar saharanpur Saharanpur 247001-saharanpur | U3: 4
A4: 3 | B4: 2200290100003 | C4: 2226CSE1023 | D4: AASTHA | E4: AJAY KUMAR | F4: A | H4: VI | I4: FEMALE | J4: aastha.2226cse1023@kiet.edu | K4: aastha962004@gmail.com | L4: 8979318253 | M4: 8923255363 | N4: A | O4: 92.6 | P4: 92.8 | Q4: 38147 | R4: 09/06/2004 | S4: HOSTELLER | T4: 8/4278 lane no 1 chikana road samrat vikram colony saharanpur saharanpur Saharanpur 247001saharanpursaharanpur | U4: 4
A5: 4 | B5: 2200290100004 | C5: 2226CSE1148 | D5: ABHA GANGWAR | E5: ASHISH KUMAR GANGWAR | F5: A | H5: VI | I5: FEMALE | J5: abha.2226cse1148@kiet.edu | K5: abhagangwar12c@gmail.com | L5: 9653040260 | M5: 9125470121 | N5: A | O5: 90 | P5: 92.8 | Q5: 38328 | R5: 07/12/2004 | S5: HOSTELLER | T5: haydil colony fatehpur fATEHPUR FATEHPUR Fatehpur 212601fATEHPURFATEHPUR | U5: 4
A6: 5 | B6: 2200290100005 | C6: 2226CSE1152 | D6: ABHAY KAUTS | E6: SUSHIL KUMAR | F6: A | H6: VI | I6: MALE | J6: abhay.2226cse1152@kiet.edu | K6: abhay14kautish8@gmail.com | L6: 9548981354 | M6: 8476948232 | N6: A | O6: 91.6 | P6: 87.6 | Q6: 37942 | R6: 17/11/2003 | S6: DAY SCHOLAR | T6: gali no. 05, bhupendrapuri, modinagar modinagar ghaziabad 201204----modinagar | U6: 4
A7: 6 | B7: 2200290100006 | C7: 2226CSE1128 | D7: ABHAY PRATAP SINGH | E7: PRAMOD KUMAR GAUTAM | F7: A | H7: VI | I7: MALE | J7: abhay.2226cse1128@kiet.edu | K7: pratapsinghabhay703@gmail.com | L7: 8869980090 | M7: 7905857441 | N7: A | O7: 76 | P7: 74.2 | Q7: 37675 | R7: 23/02/2003 | S7: DAY SCHOLAR | T7: purab kheda, civil line UNNAO Unnao 209801----UNNAO | U7: 4
A8: 7 | B8: 2200290100007 | C8: 2226CSE1042 | D8: ABHISHEK KUMAR | E8: ASHOK KUMAR SINGH | F8: A | H8: VI | I8: MALE | J8: abhishek.2226cse1042@kiet.edu | K8: abhishekkumar.06099@gmail.com | L8: 6389463172 | M8: 9616309386 | N8: A | O8: 90.8 | P8: 85.4 | Q8: 38078 | R8: 01/04/2004 | S8: HOSTELLER | T8: madvari muhalla, LAKHISARAI, bihar lakhisarai LAKHISARAI 811311----lakhisarai | U8: 4
A9: 8 | B9: 2200290100008 | C9: 2226CSE1170 | D9: ABHISHEK YADAV | E9: DAYARAM YADAV | F9: A | H9: VI | I9: MALE | J9: abhishek.2226cse1170@kiet.edu | K9: abhishekyadav276208@gmail.com | L9: 8853317393 | M9: 7985293155 | N9: A | O9: 91.17 | P9: 82.17 | Q9: 38034 | R9: 17/02/2004 | S9: DAY SCHOLAR | T9: gram tikapur post tikapur tahbarpur AZAMGARH Azamgarh 276208tahbarpurAZAMGARH | U9: 4
A10: 9 | B10: 2200290100009 | C10: 2226CSE1145 | D10: ADITI | E10: ANAND KUMAR | F10: A | H10: VI | I10: FEMALE | J10: aditi.2226cse1145@kiet.edu | K10: aditisingh6363@gamil.com | L10: 8218556570 | M10: 8588857110 | N10: A | O10: 71.6 | P10: 74.8 | Q10: 38150 | R10: 12/06/2004 | S10: DAY SCHOLAR | T10: 31 chaudhary valui gali new defence colony muradnagar GHAZIABAD Ghaziabad 201206muradnagarGHAZIABAD | U10: 4
A11: 10 | B11: 2200290100010 | C11: 2226CSE1066 | D11: ADITI AGRAWAL | E11: KAMAL KUMAR AGRAWAL | F11: A | H11: VI | I11: FEMALE | J11: aditi.2226cse1066@kiet.edu | K11: agrawaladiti125@gmail.com | L11: 8923221668 | M11: 8923484070 | N11: A | O11: 92.2 | P11: 93.2 | Q11: 38364 | R11: 12/01/2005 | S11: HOSTELLER | T11: shiv colony gali no. 2 tarfara road hathras hathras 204101----hathras | U11: 4
A12: 11 | B12: 2200290100011 | C12: 2226CSE1126 | D12: ADITI SRIVASTAVA | E12: PANKAJ SRIVASTAVA | F12: A | H12: VI | I12: FEMALE | J12: aditi.2226cse1126@kiet.edu | K12: srivastavahoney578@gmail.com | L12: 9044403621 | M12: 8604433621 | N12: A | O12: 88.2 | P12: 84.6 | Q12: 37930 | R12: 05/11/2003 | S12: DAY SCHOLAR | T12: arjunpurwa lakhimpur kheri lakhimpur kheri kheri 262701----lakhimpur kheri | U12: 4
A13: 12 | B13: 2200290100012 | C13: 2226CSE1044 | D13: ADITYA CHANDRA VERMA | E13: GYAN CHANDRA | F13: A | H13: VI | I13: MALE | J13: aditya.2226cse1044@kiet.edu | K13: adityachandraverma2003@gmail.com | L13: 7905751817 | M13: 9517007192 | N13: A | O13: 89 | P13: 78 | Q13: 37730 | R13: 19/04/2003 | S13: HOSTELLER | T13: HN52 shivpuram near paramount school koyla nagar kanpur KANPUR Kanpur Nagar 208011kanpurKANPUR | U13: 4
A14: 13 | B14: 2200290100013 | C14: 2226CSE1081 | D14: ADITYA KUMAR SHARMA | E14: GIRISH CHANDRA SHARMA | F14: A | H14: VI | I14: MALE | J14: aditya.2226cse1081@kiet.edu | K14: aditya91sharma73619@gmail.com | L14: 8955367896 | M14: 6388606390 | N14: A | O14: 83 | P14: 75 | Q14: 38211 | R14: 12/08/2004 | S14: DAY SCHOLAR | T14: 381 deoria khas, uma nagar, ward no 15 deoria DEORIA Deoria 274001deoriaDEORIA | U14: 4
A15: 14 | B15: 2200290100014 | C15: 2226CSE1138 | D15: ADNAN YASIR | E15: WASEEM AHMAD | F15: A | H15: VI | I15: MALE | J15: adnan.2226cse1138@kiet.edu | K15: mr.adnan.yasir@gmail.com | L15: 9971458997 | M15: 8953879402 | N15: A | O15: 74.2 | P15: 80.2 | Q15: 37849 | R15: 16/08/2003 | S15: HOSTELLER | T15: 137 baduzai second near ande wali gali shahjahanpur SHAHJAHANPUR 242001----shahjahanpur | U15: 4
... A68: 67 | B68: 2200290100067 | C68: 2226CSE1019 | D68: EKTA | E68: MANOJ KUMAR | F68: A | H68: VI | I68: FEMALE | J68: ekta.2226cse1019@kiet.edu | K68: ektapoonam20@gmail.com | L68: 7983766585 | M68: 9690064650 | N68: A | O68: 93.8 | P68: 93.8 | Q68: 37853 | R68: 20/08/2003 | S68: DAY SCHOLAR | T68: vill laharra post khanpur, meerut meerut 250501post - khanpur, meerut---- | U68: 4
A69: 68 | B69: 2300290109001 | C69: 2226CSE1212 | D69: ASHIQ YADAV | E69: PRADEEP KUMAR YADAV | F69: A | H69: VI | I69: MALE | J69: ashiq.2226cse1212@kiet.edu | K69: ashikyadav003@gmail.com | L69: 7985884928 | M69: 7839566014 | N69: A | O69: 75.33 | P69: --- | Q69: 38487 | R69: 15/05/2005 | S69: DAY SCHOLAR | T69: villbanguwan post baruwasagar VILLBANGUWAN POST BARUWASAGAR jhansi JHANSI 284201VILL-BANGUWAN POST BARUWASAGARjhansi | U69: 4
A70: 69 | B70: 2300290109002 | C70: 2226CSE1211 | D70: ASHWANI BAGHEL | E70: MANOJ KUMAR | F70: A | H70: VI | I70: MALE | J70: ashwani.2226cse1211@kiet.edu | K70: ashwanibaghel826@gmail.com | L70: 9027872803 | M70: 8006250981 | N70: A | O70: 75.67 | P70: 73.4 | Q70: 37726 | R70: 15/04/2003 | S70: DAY SCHOLAR | T70: village garhi bhakti line par tundla firozabad tundla firozabad 283204firozabadtundla | U70: 4
A71: 70 | B71: 2300290109003 | C71: 2226CSE1214 | D71: AYUSH SINGH | E71: SURENDRA SINGH | F71: A | H71: VI | I71: MALE | J71: ayush.2226cse1214@kiet.edu | K71: AWERT2684@GMAIL.COM | L71: 9457858543 | M71: 9415066411 | N71: A | O71: 88 | P71: 89.17 | Q71: 37552 | R71: 23/10/2002 | S71: DAY SCHOLAR | T71: BSNL EXCHANGE NEAR TOWNSHIP CHORAHA NH2 HIGHWAY AURANGABAD MATHURA UP MATHURA MATHURA 281006NH2 HIGHWAY AURANGABAD MATHURA UPMATHURA | U71: 4
A72: 71 | B72: 2300290109007 | C72: 2226CSE1202 | D72: PRASHANT SRIVASTAVA | E72: RUPESH SRIVASTAVA | F72: A | H72: VI | I72: MALE | J72: prashant.2226cse1202@kiet.edu | K72: prashantsrivastava8778@gmail.com | L72: 9760529195 | M72: 9958207089 | N72: A | O72: 72.17 | P72: --- | Q72: 38229 | R72: 30/08/2004 | S72: DAY SCHOLAR | T72: 62 takshila colony near samsung showroom agra agra 282005near samsung showroomagra | U72: 4
A73: 72 | B73: 2300290109008 | C73: 2226CSE1213 | D73: RAMIT GANGWAR | E73: MRINAL RANJAN | F73: A | H73: VI | I73: MALE | J73: ramit.2226cse1213@kiet.edu | K73: ramitgangwar@gmail.com | L73: 6398462966 | M73: 9897191101 | N73: A | O73: 69.4 | P73: --- | Q73: 38474 | R73: 02/05/2005 | S73: DAY SCHOLAR | T73: 125,post jogither, tikri mafi, pilibhit, bisalpur pilibhit PILIBHIT 262201----pilibhit | U73: 4
A74: 73 | B74: 2300290109017 | C74: 2226CSE1203 | D74: VAIBHAV SRIVASTAVA | E74: MANOJ KUMAR PARAMARTHI | F74: A | H74: VI | I74: MALE | J74: vaibhav.2226cse1203@kiet.edu | K74: vaibhavsrivastava589@gmail.com | L74: 7505957829 | N74: A | O74: 80.4 | P74: --- | Q74: 37073 | R74: 01/07/2001 | S74: DAY SCHOLAR | T74: 4 mig,INDRAPURAM COLONY SHAMSHABAD ROAD AGRA Agra 282001----AGRA | U74: 4
A75: 1 | B75: 2200290100068 | C75: 2226CSE1046 | D75: GAURAV SINGH | E75: AMAR SINGH | F75: B | H75: VI | I75: MALE | J75: gaurav.2226cse1046@kiet.edu | K75: am.singh.gaurav@gmail.com | L75: 9540812455 | M75: 8929014783 | N75: B | O75: 96 | P75: 87.6 | Q75: 38118 | R75: 11/05/2004 | S75: HOSTELLER | T75: flat no 108, shree ram gold apartments, lane no189 near snowcool, laxman vihar,phase2, sector 3a gurugram Gurgaon 122001near snowcool, laxman vihar,phase-2, sector 3agurugram | U75: 4
A76: 2 | B76: 2200290100069 | C76: 2226CSE1065 | D76: GHANATAVA VASHU THAKARAN | E76: RAJIV SINGH THAKARANN | F76: B | H76: VI | I76: MALE | J76: ghanatava.2226cse106@kiet.edu | K76: GHANATVA@GMAIL.COM | L76: 9719756197 | M76: 9719026597 | N76: B | O76: 89.83 | P76: 92.2 | Q76: 38102 | R76: 25/04/2004 | S76: HOSTELLER | T76: VILLAGE LADPUR, POST KHATAULI KHATAULI Muzaffarnagar 251201----KHATAULI | U76: 4
A77: 3 | B77: 2200290100070 | C77: 2226CSE1007 | D77: GUN SINGHAL | E77: MANOJ SINGHAL | F77: B | H77: VI | I77: FEMALE | J77: gun.2226cse1007@kiet.edu | K77: gunsinghal0810@gmail.com | L77: 8076731664 | M77: 9811113201 | N77: B | O77: 94.4 | P77: 93.2 | Q77: 38268 | R77: 08/10/2004 | S77: DAY SCHOLAR | T77: H.NO. JAGNI GANJ GHANTA GHAR, GHAZIABAD GHANTA GHAR GHAZIABAD 201001GHANTA GHAR, GHAZIABADGHANTA GHAR | U77: 4
A78: 4 | B78: 2200290100071 | C78: 2226CSE1080 | D78: HAMZA HASAN | E78: MOHD OWAIS | F78: B | H78: VI | I78: MALE | J78: hamza.2226cse1080@kiet.edu | K78: hasanhamza1792003@gmail.com | L78: 6306451258 | M78: 9415185159 | N78: B | O78: 94.2 | P78: 91.8 | Q78: 37881 | R78: 17/09/2003 | S78: HOSTELLER | T78: 610 /529 a bari enclave mosque keshav nagar nirala nagar lucknow Lucknow 226020keshav nagar nirala nagarlucknow | U78: 4
A79: 5 | B79: 2200290100072 | C79: 2226CSE1142 | D79: HARSH CHOUDHARY | E79: RAJIV KUMAR | F79: B | H79: VI | I79: MALE | J79: harsh.2226cse1142@kiet.edu | K79: choudharyharsh162@gmail.com | L79: 9667354562 | M79: 9650918585 | N79: B | O79: 66.33 | P79: 70.67 | Q79: 38059 | R79: 13/03/2004 | S79: DAY SCHOLAR | T79: house no37b bahadurpur garhi shahpur MUZAFFARNAGAR Muzaffarnagar 251318bahadurpur garhi shahpurMUZAFFARNAGAR | U79: 4
A80: 6 | B80: 2200290100073 | C80: 2226CSE1054 | D80: HARSH KUMAR SINGH | E80: ANIL KUMAR SINGH | F80: B | H80: VI | I80: MALE | J80: harsh.2226cse1054@kiet.edu | K80: 7376730571harsh@gmail.com | L80: 9838089579 | M80: 9682586076 | N80: B | O80: 96 | P80: 95.4 | Q80: 38012 | R80: 26/01/2004 | S80: HOSTELLER | T80: h.no.79 derhgawan ghazipur ghazipur 232328ghazipur---- | U80: 4
A81: 7 | B81: 2200290100074 | C81: 2226CSE1132 | D81: HARSH MAURYA | E81: SATENDRA MAURYA | F81: B | H81: VI | I81: MALE | J81: harsh.2226cse1132@kiet.edu | K81: harsh6389703067@gmail.com | L81: 9305967924 | M81: 9235350391 | N81: B | O81: 87.6 | P81: 76.4 | Q81: 38091 | R81: 14/04/2004 | S81: DAY SCHOLAR | T81: SAIDANPUR POST MURADGANJ HUSSENABAD jaunpur JAUNPUR 222002----jaunpur | U81: 4
A82: 8 | B82: 2200290100075 | C82: 2226CSE1036 | D82: HARSH MISHRA | E82: SANTOSH KUMAR MISHRA | F82: B | H82: VI | I82: MALE | J82: harsh.2226cse1036@kiet.edu | K82: mishraharsh6244@gmail.com | L82: 9044551984 | M82: 9415628252 | N82: B | O82: 85.6 | P82: 85.8 | Q82: 38400 | R82: 17/02/2005 | S82: DAY SCHOLAR | T82: 41 jainpur, lalganj ajhara lalganjajhara Pratapgarh 230132----lalganj-ajhara | U82: 4
A83: 9 | B83: 2200290100076 | C83: 2226CSE1037 | D83: HARSH PATEL | E83: RAJ BAHADUR PATEL | F83: B | H83: VI | I83: MALE | J83: harsh.2226cse1037@kiet.edu | K83: hsp209264@gmail.com | L83: 7398679789 | M83: 8924010591 | N83: B | O83: 93.17 | P83: 86.17 | Q83: 38234 | R83: 04/09/2004 | S83: HOSTELLER | T83: 102/3, juhi safed colony, juhi colony, kanpur nagar kanpur kanpur 208014----kanpur | U83: 4
A84: 10 | B84: 2200290100077 | C84: 2226CSE1040 | D84: HARSH PRATAP SINGH | E84: SUDHIR TOMAR | F84: B | H84: VI | I84: MALE | J84: harsh.2226cse1040@kiet.edu | K84: harshittomar2332@gmail.com | L84: 9368108253 | M84: 9634025765 | N84: B | O84: 85 | P84: 76.6 | Q84: 38212 | R84: 13/08/2004 | S84: DAY SCHOLAR | T84: 306, murari nagar fire station road, khurja bulandshahr Bulandshahr 203131fire station road, khurjabulandshahr | U84: 4
A85: 11 | B85: 2200290100078 | C85: 2226CSE1075 | D85: HARSH SHRIVASTAVA | E85: NAVEEN SHRIVASTAVA | F85: B | H85: VI | I85: MALE | J85: harsh.2226cse1075@kiet.edu | K85: harshcse1075@gmail.com | L85: 7307360089 | M85: 9616751137 | N85: B | O85: 74.5 | P85: 74.67 | Q85: 37686 | R85: 06/03/2003 | S85: HOSTELLER | T85: gm 1/9 veerangana nagar jhansi khas jhansi Jhansi 284128nagar jhansi khasjhansi | U85: 4
A86: 12 | B86: 2200290100079 | C86: 2226CSE1047 | D86: HARSH VERMA | E86: SUNIL KUMAR | F86: B | H86: VI | I86: MALE | J86: harsh.2226cse1047@kiet.edu | K86: harshverma2000003@gmail.com | L86: 8868827763 | M86: 9917782205 | N86: B | O86: 96.6 | P86: 94.4 | Q86: 37718 | R86: 07/04/2003 | S86: DAY SCHOLAR | T86: a85, gali no2, ram nagar, kanker khera, meerut meerut meerut 250001----meerut | U86: 4
... A120: 46 | B120: 2200290100113 | C120: 2226CSE1194 | D120: PAKHI SHARMA | E120: VINEET KUMAR SHARMA | F120: B | H120: VI | I120: FEMALE | J120: pakhi.2226cse1194@kiet.edu | K120: sharmapakhi0204@gmail.com | L120: 9650882213 | M120: 9811139463 | N120: B | O120: 92.67 | P120: 85.4 | Q120: 38170 | R120: 02/07/2004 | S120: DAY SCHOLAR | T120: g154,pratap vihar sector11 ghaziabad Ghaziabad 201009sector-11ghaziabad | U120: 4
A121: 47 | B121: 2200290100114 | C121: 2226CSE1016 | D121: PIYUSH RAJ | E121: NITESH KUMAR | F121: B | H121: VI | I121: MALE | J121: piyush.2226cse1016@kiet.edu | K121: vrnpiyush@gmail.com | L121: 6204208132 | M121: 9973628662 | N121: B | O121: --- | P121: --- | Q121: 38171 | R121: 03/07/2004 | S121: DAY SCHOLAR | T121: AMRAPALI DREAM VELLAY LA RESIDENCIAL TOWER 9 FLAT 403 noida GAUTAM BHUDD NAGAR 201306LA RESIDENCIAL TOWER 9 FLAT 403noida | U121: 4
A122: 48 | B122: 2200290100115 | C122: 2226CSE1160 | D122: PRACHI SINGH | E122: HARPAL SINGH | F122: B | H122: VI | I122: FEMALE | J122: prachi.2226cse1160@kiet.edu | K122: PRACHIS10293@GMAIL.COM | L122: 7302834387 | M122: 9927324748 | N122: B | O122: 84.8 | P122: 83.6 | Q122: 37877 | R122: 13/09/2003 | S122: HOSTELLER | T122: MOHALLA PANCHSHIL COLONY CHANDAUSI SAMBHAL MORADABAD Moradabad 244412----MORADABAD | U122: 4
A123: 49 | B123: 2200290100116 | C123: 2226CSE1006 | D123: PRACHI UPPAL | E123: PAWAN KUMAR UPPAL | F123: B | H123: VI | I123: FEMALE | J123: prachi.2226cse1006@kiet.edu | K123: prachiuppal64@gmail.com | L123: 7017325624 | M123: 7017739761 | N123: B | O123: 92.2 | P123: 92 | Q123: 38332 | R123: 11/12/2004 | S123: DAY SCHOLAR | T123: hn 65 gali no 6 brahampuri dadrana road modinagar modinagar Ghaziabad 201204modinagarmodinagar | U123: 4
A124: 50 | B124: 2200290100117 | C124: 2226CSE1172 | D124: PRAGUN PANDEY | E124: ANANDESHWAR PANDEY | F124: B | H124: VI | I124: MALE | J124: pragun.2226cse1172@kiet.edu | K124: pandeyash27748278@gmail.com | L124: 7217464487 | M124: 9412891324 | N124: B | O124: 95.8 | P124: 90.8 | Q124: 37900 | R124: 06/10/2003 | S124: DAY SCHOLAR | T124: panni ji sugar mill colony BULANDSHAHR BULANDSHAHR Bulandshahr 203001BULANDSHAHRBULANDSHAHR | U124: 4
A125: 51 | B125: 2200290100118 | C125: 2226CSE1190 | D125: PRAKRITI | E125: NEERAJ KUMAR GUPTA | F125: B | H125: VI | I125: FEMALE | J125: prakriti.2226cse1190@kiet.edu | K125: prakritiprakriti05@gmail.com | L125: 8979932953 | M125: 9761115253 | N125: B | O125: 91 | P125: 87 | Q125: 38135 | R125: 28/05/2004 | S125: DAY SCHOLAR | T125: house no71, lane2/5, krishana nagar, modinagar modinagar Ghaziabad 201204----modinagar | U125: 4
...

Sheet Sheet1
A2: 15 | B2: 2100290100145 | C2: 2125CSE1040 | D2: SAMARTH SAINI | E2: SUNIL SAINI | F2: C | H2: 4 | I2: MALE | J2: samarth.2125cse1040@kiet.edu | K2: 7302698899 | L2: 9548348144 | M2: C | N2: Suspended case
A3: 68 | B3: 2000290100180 | C3: 2024CSE1142 | D3: VAIBHAV SHARMA | E3: SUNIL KUMAR SHARMA | F3: C | H3: 4 | I3: MALE | J3: vaibhav.2024cse1142@kiet.edu | K3: 9456089031 | L3: 8535015600 | M3: C | N3: One year leave (2022-23)
A4: 30 | B4: 2000290100030 | C4: 2024CSE1127 | D4: ARPITA GUPTA | E4: SITA RAM GUPTA | F4: A | H4: 6 | I4: FEMALE | J4: arpita.2024cse1127@kiet.edu | K4: 8400394128 | L4: 9415925679 | N4: Demise
A5: 5 | B5: 2100290100135 | C5: 2125CS1026 | D5: RISHI SINGH | E5: AJAY KUMAR SINGH | F5: C | H5: 5 | I5: MALE | J5: rishi.2125cs1026@kiet.edu | K5: 8081675303 | L5: 8707616211 | M5: C | N5: Left
A6: 57 | B6: 2100290100191 | C6: 2125CSE1116 | D6: VISHESH KUMAR | E6: RADHESHYAM SINGH | F6: C | H6: 5 | I6: MALE | J6: vishesh.2125cse1116@kiet.edu | K6: 6395945318 | L6: 9411711504 | M6: C
A7: =IF('CSE II'!M40<>M7,"1",'CSE II'!A40+1) -> 40 | B7: 2428CSE2497 | C7: 2428CSE2497 | D7: AMAN SINGH | E7: ANIL KUMAR SINGH | G7: 9336297728 | H7: 9452071582 | I7: 9336523097 | J7: aman.2428cse2497@kiet.edu | K7: M | L7: CSE | M7: A | N7: Left | O7: A | P7: Village-Tetarpur ,post -pure neval,pratapgarh,Uttarpradesh
A8: =IF('CSE III'!N210<>M8,"1",'CSE III'!A210+1) -> 52 | B8: 2300290100198 | C8: 2327CSE1257 | D8: RAJARSHI YADAV | E8: ASHOK KUMAR YADAV | G8: 7007541055 | H8: 9919954471 | I8: 7007541055 | J8: rajarshi.2327cse1257@kiet.edu | K8: MALE | L8: CSE | M8: C | N8: Fail | O8: C | P8: gram bardiha , bardiha JAUNPUR JAUNPUR 222148----JAUNPUR
A9: =IF('CSE III'!N56<>M9,"1",'CSE III'!A56+1) -> 56 | B9: 2300290100057 | C9: 2327CSE1255 | D9: ANSH GOYAL | E9: DAUJI GOYAL | F9: TULSI GOYAL | G9: #N/A | H9: #N/A | I9: 9258634591 | J9: ansh.2327cse1255@kiet.edu | K9: MALE | L9: CSE | M9: A | N9: Left | O9: A | P9: mohammadpur, shashtripuram agra agr agra 282007agraagr
A10: =IF('CSE III'!N50<>M10,"1",'CSE III'!A50+1) -> 50 | B10: 2300290100050 | C10: 2327CSE1154 | D10: ANJALI KUMARI | E10: SHIV SHANKAR | G10: #N/A | H10: #N/A | I10: 8057790288 | J10: anjali.2327cse1154@kiet.edu | K10: FEMALE | L10: CSE | M10: A | N10: Left | O10: A | P10: 77, ROADWAYS COLONY BAKALPUR MATHURA Mathura 281004----BAKALPUR MATHURA
A11: =IF('CSE II'!M265<>M11,"1",'CSE II'!A265+1) -> #REF! | B11: 202401100200250 | C11: 2428CSE2419 | D11: RAHUL ORAON | E11: NARESH ORAON | G11: 6392676571 | H11: 9451897094 | I11: 6392676571 | J11: rahul.2428cse2419@kiet.edu | K11: M | L11: CSE | M11: D | N11: Left | O11: D | P11: Jb garden para rajajipuram | R11: 202401100200250
A12: =IF('CSE II'!M96<>M12,"1",'CSE II'!A96+1) -> 18 | B12: 202401100200092 | C12: 2428CSE2255 | D12: ARYAN CHAUDHARY | E12: UMESH CHANDRA | G12: 6394910656 | H12: 7652035061 | I12: 9554023136 | J12: aryan.2428cse2255@kiet.edu | K12: M | L12: CSE | M12: B | N12: Left | O12: B | P12: Vill. Bansgaon ,Kheri ,post Kaparaha | R12: 202401100200092
A13: =IF('CSE II'!M375<>M13,"1",'CSE II'!A375+1) -> 61 | B13: 2400290100353 | C13: 2428CSE1766 | D13: VISHWESH SRIVASTAVA | E13: CHANDRA PRAKASH SRIVASTAVA | G13: 8303923205 | H13: 6386914161 | I13: 8400752968 | J13: vishwesh.2428cse1766@kiet.edu | K13: M | L13: CSE | M13: E | N13: Left | O13: D | P13: Dhanipur jangiganj , bhadohi , Uttar Pradesh | Q13: 202401100200354 | R13: VISHWESH | S13: SRIVASTAVA | T13: #REF!
A14: =IF('CSE II'!M354<>M14,"1",'CSE II'!A354+1) -> 40 | B14: 2400290100331 | C14: 2428CSE2410 | D14: VAIBHAV PAL | E14: LALIT KUMAR PAL | G14: 9450190109 | H14: 8765968771 | I14: 9219718576 | J14: vaibhav.2428cse2410@kiet.edu | K14: M | L14: CSE | M14: E | N14: Left | O14: D | P14: 155A/7B, Awadhpuri Colony, Chak Ponghat, Mundera, Prayagraj | Q14: 202401100200332 | R14: VAIBHAV | S14: PAL | T14: #REF!
A15: =IF('CSE II'!M306<>M15,"1",'CSE II'!A306+1) -> #REF! | B15: 2400290100291 | C15: 2428CSE2222 | D15: SHIVANSH BHATT | E15: LATE SANJAY KUMAR BHATT | G15: 6390111107 | H15: 8601473111 | I15: 8601473111 | J15: shivansh.2428cse2222@kiet.edu | K15: M | L15: CSE | M15: D | N15: Re-admitted in first yr | P15: D-36A d-block sector 4 Lajpat Nagar sahibabad ghaziabad | Q15: 202401100200292 | R15: SHIVANSH | S15: BHATT | T15: #REF!
